<?xml version='1.0'?>
<sdf version='1.7'>
  <model name='sawppy'>
    <pose>0 0 0.21 0 0 0</pose>
    <link name='base_link'>
      <inertial>
        <pose>0 0 0 0 0 0</pose>
        <mass>1.01</mass>
        <inertia>
          <ixx>0.00748967</ixx>
          <ixy>0</ixy>
          <ixz>0</ixz>
          <iyy>0.015773</iyy>
          <iyz>0</iyz>
          <izz>0.021821</izz>
        </inertia>
      </inertial>
      <collision name='base_link_collision'>
        <pose>0 0 0 0 -0 0</pose>
        <geometry>
          <box>
            <size>0.01 0.01 0.01</size>
          </box>
        </geometry>
        <surface>
          <contact>
            <ode/>
          </contact>
          <friction>
            <ode/>
          </friction>
        </surface>
      </collision>
      <collision name='base_link_fixed_joint_lump__body_box_link_collision_1'>
        <pose>0 0 0 0 -0 0</pose>
        <geometry>
          <box>
            <size>0.425 0.285 0.093</size>
          </box>
        </geometry>
        <surface>
          <contact>
            <ode/>
          </contact>
          <friction>
            <ode/>
          </friction>
        </surface>
      </collision>
      <visual name='base_link_visual'>
        <pose>0 0 0 0 -0 0</pose>
        <geometry>
          <box>
            <size>0.01 0.01 0.01</size>
          </box>
        </geometry>
        <material>
          <script>
            <name>Gazebo/Orange</name>
            <uri>file://media/materials/scripts/gazebo.material</uri>
          </script>
        </material>
      </visual>
      <visual name='base_link_fixed_joint_lump__body_box_link_visual_1'>
        <pose>0 0 0 0 -0 0</pose>
        <geometry>
          <mesh>
            <scale>1 1 1</scale>
            <uri>model://sawppy/meshes/bases/body_box.stl</uri>
          </mesh>
        </geometry>
        <material>
          <script>
            <name>Gazebo/DarkGray</name>
            <uri>file://media/materials/scripts/gazebo.material</uri>
          </script>
        </material>
      </visual>
      <velocity_decay/>
      <gravity>1</gravity>
      <velocity_decay/>
    </link>
    <joint name='diff_brace_joint' type='revolute'>
      <pose relative_to='base_link'>0 0 0.0681 0 -0 0</pose>
      <parent>base_link</parent>
      <child>diff_brace_link</child>
      <axis>
        <initial_position>0</initial_position>
        <xyz>0 0 1</xyz>
        <limit>
          <lower>-0.785398</lower>
          <upper>0.785398</upper>
          <effort>100</effort>
          <velocity>100</velocity>
        </limit>
        <dynamics>
          <spring_reference>0</spring_reference>
          <spring_stiffness>0</spring_stiffness>
          <damping>0.1</damping>
          <friction>0.1</friction>
        </dynamics>
      </axis>
      <physics>
        <provide_feedback>1</provide_feedback>
        <ode>
          <implicit_spring_damper>1</implicit_spring_damper>
          <cfm_damping>1</cfm_damping>
          <limit>
            <cfm>0</cfm>
            <erp>0.2</erp>
          </limit>
          <provide_feedback>1</provide_feedback>
        </ode>
      </physics>
    </joint>
    <link name='diff_brace_link'>
      <pose relative_to='diff_brace_joint'>0 0 0 0 -0 0</pose>
      <inertial>
        <pose>0 0 0 0 -0 1.5708</pose>
        <mass>0.1</mass>
        <inertia>
          <ixx>3.75e-06</ixx>
          <ixy>0</ixy>
          <ixz>0</ixz>
          <iyy>0.000335208</iyy>
          <iyz>0</iyz>
          <izz>0.000335208</izz>
        </inertia>
      </inertial>
      <collision name='diff_brace_link_collision'>
        <pose>0 0 0 0 -0 1.5708</pose>
        <geometry>
          <box>
            <size>0.2 0.015 0.015</size>
          </box>
        </geometry>
        <surface>
          <contact>
            <ode/>
          </contact>
          <friction>
            <ode/>
          </friction>
        </surface>
      </collision>
      <visual name='diff_brace_link_visual'>
        <pose>0 0 0 0 -0 0</pose>
        <geometry>
          <mesh>
            <scale>1 1 1</scale>
            <uri>model://sawppy/meshes/bases/differential.stl</uri>
          </mesh>
        </geometry>
        <material>
          <script>
            <name>Gazebo/DarkGray</name>
            <uri>file://media/materials/scripts/gazebo.material</uri>
          </script>
        </material>
      </visual>
      <gravity>1</gravity>
      <velocity_decay/>
    </link>
    <!-- <joint name='imu_joint' type='fixed'>
      <pose relative_to='base_link'>0.11 -0.043 0.005 0 -0 0</pose>
      <parent>base_link</parent>
      <child>imu</child>
      <axis>
        <dynamics>
          <spring_reference>0</spring_reference>
          <spring_stiffness>0</spring_stiffness>
        </dynamics>
        <xyz>0 0 1</xyz>
        <limit>
          <lower>-1e+16</lower>
          <upper>1e+16</upper>
        </limit>
      </axis>
      <physics>
        <ode>
          <limit>
            <cfm>0</cfm>
            <erp>0.2</erp>
          </limit>
        </ode>
      </physics>
    </joint>
    <link name='imu'>
      <pose relative_to='imu_joint'>0 0 0 0 -0 0</pose>
      <inertial>
        <pose>0 0 0 0 -0 0</pose>
        <mass>0.004</mass>
        <inertia>
          <ixx>2.33667e-07</ixx>
          <ixy>0</ixy>
          <ixz>0</ixz>
          <iyy>3.28667e-07</iyy>
          <iyz>0</iyz>
          <izz>5.45667e-07</izz>
        </inertia>
      </inertial>
      <collision name='imu_collision'>
        <pose>0 0 0 0 -0 0</pose>
        <geometry>
          <box>
            <size>0.031 0.026 0.005</size>
          </box>
        </geometry>
        <surface>
          <contact>
            <ode/>
          </contact>
          <friction>
            <ode/>
          </friction>
        </surface>
      </collision>
      <visual name='imu_visual'>
        <pose>0 0 0 0 -0 0</pose>
        <geometry>
          <box>
            <size>0.031 0.026 0.005</size>
          </box>
        </geometry>
        <material>
          <script>
            <name>Gazebo/Green</name>
            <uri>file://media/materials/scripts/gazebo.material</uri>
          </script>
        </material>
      </visual>
      <gravity>1</gravity>
      <velocity_decay/>
      <sensor name='imu_sensor' type='imu'>
        <always_on>1</always_on>
        <update_rate>50</update_rate>
        <visualize>1</visualize>
        <topic>sensors/imu</topic>
        <pose>0 0 0 0 -0 0</pose>
        <imu>
          <topic>sensors/imu</topic>
        </imu>
        <plugin name='imu_plugin' filename='libgazebo_ros_imu_sensor.so'>
          <gaussianNoise>0.0</gaussianNoise>
          <always_on>1</always_on>
          <updateRateHz>50</updateRateHz>
          <topicName>sensors/imu</topicName>
          <frameName>imu</frameName>
          <bodyName>imu</bodyName>
          <xyzOffset>0 0 0</xyzOffset>
          <rpyOffset>0 0 0</rpyOffset>
        </plugin>
      </sensor>
    </link> -->
    <joint name='laser_joint' type='fixed'>
      <pose relative_to='base_link'>0.152 0.078 0.05 0 -0 0</pose>
      <parent>base_link</parent>
      <child>laser</child>
      <axis>
        <dynamics>
          <spring_reference>0</spring_reference>
          <spring_stiffness>0</spring_stiffness>
        </dynamics>
        <xyz>0 0 1</xyz>
        <limit>
          <lower>-1e+16</lower>
          <upper>1e+16</upper>
        </limit>
      </axis>
      <physics>
        <ode>
          <limit>
            <cfm>0</cfm>
            <erp>0.2</erp>
          </limit>
        </ode>
      </physics>
    </joint>
    <link name='laser'>
      <pose relative_to='laser_joint'>0 0 0 0 -0 0</pose>
      <inertial>
        <pose>0 0 0 0 -0 0</pose>
        <mass>0.15</mass>
        <inertia>
          <ixx>9.09375e-05</ixx>
          <ixy>0</ixy>
          <ixz>0</ixz>
          <iyy>9.09375e-05</iyy>
          <iyz>0</iyz>
          <izz>9.1875e-05</izz>
        </inertia>
      </inertial>
      <collision name='laser_collision'>
        <pose>0 0 0 0 -0 0</pose>
        <geometry>
          <cylinder>
            <length>0.06</length>
            <radius>0.035</radius>
          </cylinder>
        </geometry>
        <surface>
          <contact>
            <ode/>
          </contact>
          <friction>
            <ode/>
          </friction>
        </surface>
      </collision>
      <visual name='laser_visual'>
        <pose>0 0 0 0 -0 0</pose>
        <geometry>
          <mesh>
            <scale>1 1 1</scale>
            <uri>model://sawppy/meshes/sensors/rplidar_a1_assembly_low.stl</uri>
          </mesh>
        </geometry>
        <material>
          <script>
            <name>Gazebo/White</name>
            <uri>file://media/materials/scripts/gazebo.material</uri>
          </script>
        </material>
      </visual>
      <gravity>1</gravity>
      <velocity_decay/>
      <!-- <sensor name='laser_sensor' type='gpu_ray'>
        <always_on>1</always_on>
        <update_rate>5</update_rate>
        <visualize>0</visualize>
        <topic>sensors/laser</topic>
        <pose>0 0 0.045 0 -0 0</pose>
        <ray>
          <scan>
            <horizontal>
              <samples>360</samples>
              <resolution>1</resolution>
              <min_angle>-3.14159</min_angle>
              <max_angle>3.14159</max_angle>
            </horizontal>
            <vertical>
              <samples>1</samples>
              <resolution>1</resolution>
              <min_angle>0</min_angle>
              <max_angle>0</max_angle>
            </vertical>
          </scan>
          <range>
            <min>0.1</min>
            <max>12</max>
            <resolution>0.05</resolution>
          </range>
          <noise>
            <type>gaussian</type>
            <mean>0</mean>
            <stddev>0.01</stddev>
          </noise>
        </ray>
        <plugin name='gazebo_ros_laser' filename='libgazebo_ros_gpu_laser.so'>
          <frameName>laser</frameName>
          <topicName>sensors/laser</topicName>
        </plugin>
      </sensor> -->
    </link>
    <joint name='left_rocker_joint' type='revolute'>
      <pose relative_to='base_link'>0.071 0.155 0.0118 0 -0 0</pose>
      <parent>base_link</parent>
      <child>left_rocker_link</child>
      <axis>
        <initial_position>0</initial_position>
        <xyz>0 1 0</xyz>
        <limit>
          <lower>-1e+16</lower>
          <upper>1e+16</upper>
        </limit>
        <dynamics>
          <spring_reference>0</spring_reference>
          <spring_stiffness>0</spring_stiffness>
          <damping>0.1</damping>
          <friction>0.1</friction>
        </dynamics>
      </axis>
      <physics>
        <provide_feedback>1</provide_feedback>
        <ode>
          <implicit_spring_damper>1</implicit_spring_damper>
          <cfm_damping>1</cfm_damping>
          <limit>
            <cfm>0</cfm>
            <erp>0.2</erp>
          </limit>
          <provide_feedback>1</provide_feedback>
        </ode>
      </physics>
    </joint>
    <link name='left_rocker_link'>
      <pose relative_to='left_rocker_joint'>0 0 0 0 -0 0</pose>
      <inertial>
        <pose>0 0 0 0 -0 0</pose>
        <mass>0.25</mass>
        <inertia>
          <ixx>9.375e-06</ixx>
          <ixy>0</ixy>
          <ixz>0</ixz>
          <iyy>0.000213021</iyy>
          <iyz>0</iyz>
          <izz>0.000213021</izz>
        </inertia>
      </inertial>
      <collision name='left_rocker_link_collision'>
        <pose>0 0 0 0 -0 0</pose>
        <geometry>
          <box>
            <size>0.1 0.015 0.015</size>
          </box>
        </geometry>
        <surface>
          <contact>
            <ode/>
          </contact>
          <friction>
            <ode/>
          </friction>
        </surface>
      </collision>
      <visual name='left_rocker_link_visual'>
        <pose>0 0 0 0 -0 0</pose>
        <geometry>
          <mesh>
            <scale>1 1 1</scale>
            <uri>model://sawppy/meshes/bases/left_rocker_asm.stl</uri>
          </mesh>
        </geometry>
        <material>
          <script>
            <name>Gazebo/DarkGray</name>
            <uri>file://media/materials/scripts/gazebo.material</uri>
          </script>
        </material>
      </visual>
      <gravity>1</gravity>
      <velocity_decay/>
    </link>
    <joint name='front_left_steer_joint' type='revolute'>
      <pose relative_to='left_rocker_link'>0.2116 0.075 -0.0279 0 -0 0</pose>
      <parent>left_rocker_link</parent>
      <child>front_left_steer_link</child>
      <axis>
        <initial_position>0</initial_position>
        <xyz>0 0 1</xyz>
        <limit>
          <lower>-1e+16</lower>
          <upper>1e+16</upper>
        </limit>
        <dynamics>
          <spring_reference>0</spring_reference>
          <spring_stiffness>0</spring_stiffness>
          <damping>0.1</damping>
          <friction>0.1</friction>
        </dynamics>
      </axis>
      <physics>
        <provide_feedback>1</provide_feedback>
        <ode>
          <limit>
            <cfm>0</cfm>
            <erp>0.2</erp>
          </limit>
          <provide_feedback>1</provide_feedback>
        </ode>
      </physics>
    </joint>
    <link name='front_left_steer_link'>
      <pose relative_to='front_left_steer_joint'>0 0 0 0 -0 0</pose>
      <inertial>
        <pose>0 0 0 0 -0 0</pose>
        <mass>0.25</mass>
        <inertia>
          <ixx>0.000416667</ixx>
          <ixy>0</ixy>
          <ixz>0</ixz>
          <iyy>0.000416667</iyy>
          <iyz>0</iyz>
          <izz>0.000416667</izz>
        </inertia>
      </inertial>
      <collision name='front_left_steer_link_collision'>
        <pose>0 0 0 0 -0 0</pose>
        <geometry>
          <box>
            <size>0.1 0.1 0.1</size>
          </box>
        </geometry>
        <surface>
          <contact>
            <ode/>
          </contact>
          <friction>
            <ode/>
          </friction>
        </surface>
      </collision>
      <visual name='front_left_steer_link_visual'>
        <pose>0 0 0 0 -0 0</pose>
        <geometry>
          <mesh>
            <scale>1 1 1</scale>
            <uri>model://sawppy/meshes/bases/front_left_steering_asm.stl</uri>
          </mesh>
        </geometry>
        <material>
          <script>
            <name>Gazebo/DarkGray</name>
            <uri>file://media/materials/scripts/gazebo.material</uri>
          </script>
        </material>
      </visual>
      <gravity>1</gravity>
      <velocity_decay/>
    </link>
    <joint name='front_left_wheel_joint' type='revolute'>
      <pose relative_to='front_left_steer_link'>0 0 -0.132 0 -0 0</pose>
      <parent>front_left_steer_link</parent>
      <child>front_left_wheel_link</child>
      <axis>
        <initial_position>0</initial_position>
        <xyz>0 1 0</xyz>
        <limit>
          <lower>-1e+16</lower>
          <upper>1e+16</upper>
        </limit>
        <dynamics>
          <spring_reference>0</spring_reference>
          <spring_stiffness>0</spring_stiffness>
          <damping>0.01</damping>
          <friction>0.01</friction>
        </dynamics>
      </axis>
      <physics>
        <provide_feedback>1</provide_feedback>
        <ode>
          <limit>
            <cfm>0</cfm>
            <erp>0.2</erp>
          </limit>
          <provide_feedback>1</provide_feedback>
        </ode>
      </physics>
    </joint>
    <link name='front_left_wheel_link'>
      <pose relative_to='front_left_wheel_joint'>0 0 0 0 -0 0</pose>
      <inertial>
        <pose>0 0 0 0 -0 0</pose>
        <mass>0.25</mass>
        <inertia>
          <ixx>0.000433333</ixx>
          <ixy>0</ixy>
          <ixz>0</ixz>
          <iyy>0.000433333</iyy>
          <iyz>0</iyz>
          <izz>0.00045</izz>
        </inertia>
      </inertial>
      <collision name='front_left_wheel_link_collision'>
        <pose>0 0 0 1.5708 -0 0</pose>
        <geometry>
          <cylinder>
            <length>0.1</length>
            <radius>0.06</radius>
          </cylinder>
        </geometry>
        <surface>
          <contact>
            <ode/>
          </contact>
          <friction>
            <ode/>
          </friction>
        </surface>
      </collision>
      <visual name='front_left_wheel_link_visual'>
        <pose>0 0 0 1.5708 -0 0</pose>
        <geometry>
          <mesh>
            <scale>1 1 1</scale>
            <uri>model://sawppy/meshes/wheels/wheel_asm.stl</uri>
          </mesh>
        </geometry>
        <material>
          <script>
            <name>Gazebo/DarkGray</name>
            <uri>file://media/materials/scripts/gazebo.material</uri>
          </script>
        </material>
      </visual>
      <gravity>1</gravity>
      <velocity_decay/>
    </link>
    <joint name='left_bogie_joint' type='revolute'>
      <pose relative_to='left_rocker_link'>-0.181 0.025 -0.062 0 -0 0</pose>
      <parent>left_rocker_link</parent>
      <child>left_bogie_link</child>
      <axis>
        <initial_position>0</initial_position>
        <xyz>0 1 0</xyz>
        <limit>
          <lower>-0.785398</lower>
          <upper>0.785398</upper>
          <effort>100</effort>
          <velocity>100</velocity>
        </limit>
        <dynamics>
          <spring_reference>0</spring_reference>
          <spring_stiffness>0</spring_stiffness>
          <damping>0.1</damping>
          <friction>0.1</friction>
        </dynamics>
      </axis>
      <physics>
        <provide_feedback>1</provide_feedback>
        <ode>
          <implicit_spring_damper>1</implicit_spring_damper>
          <cfm_damping>1</cfm_damping>
          <limit>
            <cfm>0</cfm>
            <erp>0.2</erp>
          </limit>
          <provide_feedback>1</provide_feedback>
        </ode>
      </physics>
    </joint>
    <link name='left_bogie_link'>
      <pose relative_to='left_bogie_joint'>0 0 0 0 -0 0</pose>
      <inertial>
        <pose>0 0 0 0 -0 0</pose>
        <mass>0.25</mass>
        <inertia>
          <ixx>9.375e-06</ixx>
          <ixy>0</ixy>
          <ixz>0</ixz>
          <iyy>0.000213021</iyy>
          <iyz>0</iyz>
          <izz>0.000213021</izz>
        </inertia>
      </inertial>
      <collision name='left_bogie_link_collision'>
        <pose>0 0 0 0 -0 0</pose>
        <geometry>
          <box>
            <size>0.1 0.015 0.015</size>
          </box>
        </geometry>
        <surface>
          <contact>
            <ode/>
          </contact>
          <friction>
            <ode/>
          </friction>
        </surface>
      </collision>
      <visual name='left_bogie_link_visual'>
        <pose>0 0 0 0 -0 0</pose>
        <geometry>
          <mesh>
            <scale>1 1 1</scale>
            <uri>model://sawppy/meshes/bases/left_bogie_asm.stl</uri>
          </mesh>
        </geometry>
        <material>
          <script>
            <name>Gazebo/DarkGray</name>
            <uri>file://media/materials/scripts/gazebo.material</uri>
          </script>
        </material>
      </visual>
      <gravity>1</gravity>
      <velocity_decay/>
    </link>
    <joint name='back_left_steer_joint' type='revolute'>
      <pose relative_to='left_bogie_link'>-0.149 0.05 0.0338 0 -0 0</pose>
      <parent>left_bogie_link</parent>
      <child>back_left_steer_link</child>
      <axis>
        <initial_position>0</initial_position>
        <xyz>0 0 1</xyz>
        <limit>
          <lower>-1e+16</lower>
          <upper>1e+16</upper>
        </limit>
        <dynamics>
          <spring_reference>0</spring_reference>
          <spring_stiffness>0</spring_stiffness>
          <damping>0.1</damping>
          <friction>0.1</friction>
        </dynamics>
      </axis>
      <physics>
        <provide_feedback>1</provide_feedback>
        <ode>
          <limit>
            <cfm>0</cfm>
            <erp>0.2</erp>
          </limit>
          <provide_feedback>1</provide_feedback>
        </ode>
      </physics>
    </joint>
    <link name='back_left_steer_link'>
      <pose relative_to='back_left_steer_joint'>0 0 0 0 -0 0</pose>
      <inertial>
        <pose>0 0 0 0 -0 0</pose>
        <mass>0.25</mass>
        <inertia>
          <ixx>0.000416667</ixx>
          <ixy>0</ixy>
          <ixz>0</ixz>
          <iyy>0.000416667</iyy>
          <iyz>0</iyz>
          <izz>0.000416667</izz>
        </inertia>
      </inertial>
      <collision name='back_left_steer_link_collision'>
        <pose>0 0 0 0 -0 0</pose>
        <geometry>
          <box>
            <size>0.1 0.1 0.1</size>
          </box>
        </geometry>
        <surface>
          <contact>
            <ode/>
          </contact>
          <friction>
            <ode/>
          </friction>
        </surface>
      </collision>
      <visual name='back_left_steer_link_visual'>
        <pose>0 0 0 0 -0 0</pose>
        <geometry>
          <mesh>
            <scale>1 1 1</scale>
            <uri>model://sawppy/meshes/bases/back_left_steering_asm.stl</uri>
          </mesh>
        </geometry>
        <material>
          <script>
            <name>Gazebo/DarkGray</name>
            <uri>file://media/materials/scripts/gazebo.material</uri>
          </script>
        </material>
      </visual>
      <gravity>1</gravity>
      <velocity_decay/>
    </link>
    <joint name='back_left_wheel_joint' type='revolute'>
      <pose relative_to='back_left_steer_link'>0 0 -0.132 0 -0 0</pose>
      <parent>back_left_steer_link</parent>
      <child>back_left_wheel_link</child>
      <axis>
        <initial_position>0</initial_position>
        <xyz>0 1 0</xyz>
        <limit>
          <lower>-1e+16</lower>
          <upper>1e+16</upper>
        </limit>
        <dynamics>
          <spring_reference>0</spring_reference>
          <spring_stiffness>0</spring_stiffness>
          <damping>0.01</damping>
          <friction>0.01</friction>
        </dynamics>
      </axis>
      <physics>
        <provide_feedback>1</provide_feedback>
        <ode>
          <limit>
            <cfm>0</cfm>
            <erp>0.2</erp>
          </limit>
          <provide_feedback>1</provide_feedback>
        </ode>
      </physics>
    </joint>
    <link name='back_left_wheel_link'>
      <pose relative_to='back_left_wheel_joint'>0 0 0 0 -0 0</pose>
      <inertial>
        <pose>0 0 0 0 -0 0</pose>
        <mass>0.25</mass>
        <inertia>
          <ixx>0.000433333</ixx>
          <ixy>0</ixy>
          <ixz>0</ixz>
          <iyy>0.000433333</iyy>
          <iyz>0</iyz>
          <izz>0.00045</izz>
        </inertia>
      </inertial>
      <collision name='back_left_wheel_link_collision'>
        <pose>0 0 0 1.5708 -0 0</pose>
        <geometry>
          <cylinder>
            <length>0.1</length>
            <radius>0.06</radius>
          </cylinder>
        </geometry>
        <surface>
          <contact>
            <ode/>
          </contact>
          <friction>
            <ode/>
          </friction>
        </surface>
      </collision>
      <visual name='back_left_wheel_link_visual'>
        <pose>0 0 0 1.5708 -0 0</pose>
        <geometry>
          <mesh>
            <scale>1 1 1</scale>
            <uri>model://sawppy/meshes/wheels/wheel_asm.stl</uri>
          </mesh>
        </geometry>
        <material>
          <script>
            <name>Gazebo/DarkGray</name>
            <uri>file://media/materials/scripts/gazebo.material</uri>
          </script>
        </material>
      </visual>
      <gravity>1</gravity>
      <velocity_decay/>
    </link>
    <joint name='mid_left_wheel_joint' type='revolute'>
      <pose relative_to='left_bogie_link'>0.1063 0.0929 -0.0959 0 -0 0</pose>
      <parent>left_bogie_link</parent>
      <child>mid_left_wheel_link</child>
      <axis>
        <initial_position>0</initial_position>
        <xyz>0 1 0</xyz>
        <limit>
          <lower>-1e+16</lower>
          <upper>1e+16</upper>
        </limit>
        <dynamics>
          <spring_reference>0</spring_reference>
          <spring_stiffness>0</spring_stiffness>
          <damping>0.01</damping>
          <friction>0.01</friction>
        </dynamics>
      </axis>
      <physics>
        <provide_feedback>1</provide_feedback>
        <ode>
          <limit>
            <cfm>0</cfm>
            <erp>0.2</erp>
          </limit>
          <provide_feedback>1</provide_feedback>
        </ode>
      </physics>
    </joint>
    <link name='mid_left_wheel_link'>
      <pose relative_to='mid_left_wheel_joint'>0 0 0 0 -0 0</pose>
      <inertial>
        <pose>0 0 0 0 -0 0</pose>
        <mass>0.25</mass>
        <inertia>
          <ixx>0.000433333</ixx>
          <ixy>0</ixy>
          <ixz>0</ixz>
          <iyy>0.000433333</iyy>
          <iyz>0</iyz>
          <izz>0.00045</izz>
        </inertia>
      </inertial>
      <collision name='mid_left_wheel_link_collision'>
        <pose>0 0 0 1.5708 -0 0</pose>
        <geometry>
          <cylinder>
            <length>0.1</length>
            <radius>0.06</radius>
          </cylinder>
        </geometry>
        <surface>
          <contact>
            <ode/>
          </contact>
          <friction>
            <ode/>
          </friction>
        </surface>
      </collision>
      <visual name='mid_left_wheel_link_visual'>
        <pose>0 0 0 1.5708 -0 0</pose>
        <geometry>
          <mesh>
            <scale>1 1 1</scale>
            <uri>model://sawppy/meshes/wheels/wheel_asm.stl</uri>
          </mesh>
        </geometry>
        <material>
          <script>
            <name>Gazebo/DarkGray</name>
            <uri>file://media/materials/scripts/gazebo.material</uri>
          </script>
        </material>
      </visual>
      <gravity>1</gravity>
      <velocity_decay/>
    </link>
    <joint name='right_rocker_joint' type='revolute'>
      <pose relative_to='base_link'>0.071 -0.155 0.0118 0 -0 0</pose>
      <parent>base_link</parent>
      <child>right_rocker_link</child>
      <axis>
        <initial_position>0</initial_position>
        <xyz>0 1 0</xyz>
        <limit>
          <lower>-1e+16</lower>
          <upper>1e+16</upper>
        </limit>
        <dynamics>
          <spring_reference>0</spring_reference>
          <spring_stiffness>0</spring_stiffness>
          <damping>0.1</damping>
          <friction>0.1</friction>
        </dynamics>
      </axis>
      <physics>
        <provide_feedback>1</provide_feedback>
        <ode>
          <implicit_spring_damper>1</implicit_spring_damper>
          <cfm_damping>1</cfm_damping>
          <limit>
            <cfm>0</cfm>
            <erp>0.2</erp>
          </limit>
          <provide_feedback>1</provide_feedback>
        </ode>
      </physics>
    </joint>
    <link name='right_rocker_link'>
      <pose relative_to='right_rocker_joint'>0 0 0 0 -0 0</pose>
      <inertial>
        <pose>0 0 0 0 -0 0</pose>
        <mass>0.25</mass>
        <inertia>
          <ixx>9.375e-06</ixx>
          <ixy>0</ixy>
          <ixz>0</ixz>
          <iyy>0.000213021</iyy>
          <iyz>0</iyz>
          <izz>0.000213021</izz>
        </inertia>
      </inertial>
      <collision name='right_rocker_link_collision'>
        <pose>0 0 0 0 -0 0</pose>
        <geometry>
          <box>
            <size>0.1 0.015 0.015</size>
          </box>
        </geometry>
        <surface>
          <contact>
            <ode/>
          </contact>
          <friction>
            <ode/>
          </friction>
        </surface>
      </collision>
      <visual name='right_rocker_link_visual'>
        <pose>0 0 0 0 -0 0</pose>
        <geometry>
          <mesh>
            <scale>1 1 1</scale>
            <uri>model://sawppy/meshes/bases/right_rocker_asm.stl</uri>
          </mesh>
        </geometry>
        <material>
          <script>
            <name>Gazebo/DarkGray</name>
            <uri>file://media/materials/scripts/gazebo.material</uri>
          </script>
        </material>
      </visual>
      <gravity>1</gravity>
      <velocity_decay/>
    </link>
    <joint name='front_right_steer_joint' type='revolute'>
      <pose relative_to='right_rocker_link'>0.2116 -0.075 -0.0279 0 -0 0</pose>
      <parent>right_rocker_link</parent>
      <child>front_right_steer_link</child>
      <axis>
        <initial_position>0</initial_position>
        <xyz>0 0 1</xyz>
        <limit>
          <lower>-1e+16</lower>
          <upper>1e+16</upper>
        </limit>
        <dynamics>
          <spring_reference>0</spring_reference>
          <spring_stiffness>0</spring_stiffness>
          <damping>0.1</damping>
          <friction>0.1</friction>
        </dynamics>
      </axis>
      <physics>
        <provide_feedback>1</provide_feedback>
        <ode>
          <limit>
            <cfm>0</cfm>
            <erp>0.2</erp>
          </limit>
          <provide_feedback>1</provide_feedback>
        </ode>
      </physics>
    </joint>
    <link name='front_right_steer_link'>
      <pose relative_to='front_right_steer_joint'>0 0 0 0 -0 0</pose>
      <inertial>
        <pose>0 0 0 0 -0 0</pose>
        <mass>0.25</mass>
        <inertia>
          <ixx>0.000416667</ixx>
          <ixy>0</ixy>
          <ixz>0</ixz>
          <iyy>0.000416667</iyy>
          <iyz>0</iyz>
          <izz>0.000416667</izz>
        </inertia>
      </inertial>
      <collision name='front_right_steer_link_collision'>
        <pose>0 0 0 0 -0 0</pose>
        <geometry>
          <box>
            <size>0.1 0.1 0.1</size>
          </box>
        </geometry>
        <surface>
          <contact>
            <ode/>
          </contact>
          <friction>
            <ode/>
          </friction>
        </surface>
      </collision>
      <visual name='front_right_steer_link_visual'>
        <pose>0 0 0 0 -0 0</pose>
        <geometry>
          <mesh>
            <scale>1 1 1</scale>
            <uri>model://sawppy/meshes/bases/front_right_steering_asm.stl</uri>
          </mesh>
        </geometry>
        <material>
          <script>
            <name>Gazebo/DarkGray</name>
            <uri>file://media/materials/scripts/gazebo.material</uri>
          </script>
        </material>
      </visual>
      <gravity>1</gravity>
      <velocity_decay/>
    </link>
    <joint name='front_right_wheel_joint' type='revolute'>
      <pose relative_to='front_right_steer_link'>0 0 -0.132 0 -0 0</pose>
      <parent>front_right_steer_link</parent>
      <child>front_right_wheel_link</child>
      <axis>
        <initial_position>0</initial_position>
        <xyz>0 1 0</xyz>
        <limit>
          <lower>-1e+16</lower>
          <upper>1e+16</upper>
        </limit>
        <dynamics>
          <spring_reference>0</spring_reference>
          <spring_stiffness>0</spring_stiffness>
          <damping>0.01</damping>
          <friction>0.01</friction>
        </dynamics>
      </axis>
      <physics>
        <provide_feedback>1</provide_feedback>
        <ode>
          <limit>
            <cfm>0</cfm>
            <erp>0.2</erp>
          </limit>
          <provide_feedback>1</provide_feedback>
        </ode>
      </physics>
    </joint>
    <link name='front_right_wheel_link'>
      <pose relative_to='front_right_wheel_joint'>0 0 0 0 -0 0</pose>
      <inertial>
        <pose>0 0 0 0 -0 0</pose>
        <mass>0.25</mass>
        <inertia>
          <ixx>0.000433333</ixx>
          <ixy>0</ixy>
          <ixz>0</ixz>
          <iyy>0.000433333</iyy>
          <iyz>0</iyz>
          <izz>0.00045</izz>
        </inertia>
      </inertial>
      <collision name='front_right_wheel_link_collision'>
        <pose>0 0 0 -1.5708 0 0</pose>
        <geometry>
          <cylinder>
            <length>0.1</length>
            <radius>0.06</radius>
          </cylinder>
        </geometry>
        <surface>
          <contact>
            <ode/>
          </contact>
          <friction>
            <ode/>
          </friction>
        </surface>
      </collision>
      <visual name='front_right_wheel_link_visual'>
        <pose>0 0 0 -1.5708 0 0</pose>
        <geometry>
          <mesh>
            <scale>1 1 1</scale>
            <uri>model://sawppy/meshes/wheels/wheel_asm.stl</uri>
          </mesh>
        </geometry>
        <material>
          <script>
            <name>Gazebo/DarkGray</name>
            <uri>file://media/materials/scripts/gazebo.material</uri>
          </script>
        </material>
      </visual>
      <gravity>1</gravity>
      <velocity_decay/>
    </link>
    <joint name='right_bogie_joint' type='revolute'>
      <pose relative_to='right_rocker_link'>-0.181 -0.025 -0.062 0 -0 0</pose>
      <parent>right_rocker_link</parent>
      <child>right_bogie_link</child>
      <axis>
        <initial_position>0</initial_position>
        <xyz>0 1 0</xyz>
        <limit>
          <lower>-0.785398</lower>
          <upper>0.785398</upper>
          <effort>100</effort>
          <velocity>100</velocity>
        </limit>
        <dynamics>
          <spring_reference>0</spring_reference>
          <spring_stiffness>0</spring_stiffness>
          <damping>0.1</damping>
          <friction>0.1</friction>
        </dynamics>
      </axis>
      <physics>
        <provide_feedback>1</provide_feedback>
        <ode>
          <implicit_spring_damper>1</implicit_spring_damper>
          <cfm_damping>1</cfm_damping>
          <limit>
            <cfm>0</cfm>
            <erp>0.2</erp>
          </limit>
          <provide_feedback>1</provide_feedback>
        </ode>
      </physics>
    </joint>
    <link name='right_bogie_link'>
      <pose relative_to='right_bogie_joint'>0 0 0 0 -0 0</pose>
      <inertial>
        <pose>0 0 0 0 -0 0</pose>
        <mass>0.25</mass>
        <inertia>
          <ixx>9.375e-06</ixx>
          <ixy>0</ixy>
          <ixz>0</ixz>
          <iyy>0.000213021</iyy>
          <iyz>0</iyz>
          <izz>0.000213021</izz>
        </inertia>
      </inertial>
      <collision name='right_bogie_link_collision'>
        <pose>0 0 0 0 -0 0</pose>
        <geometry>
          <box>
            <size>0.1 0.015 0.015</size>
          </box>
        </geometry>
        <surface>
          <contact>
            <ode/>
          </contact>
          <friction>
            <ode/>
          </friction>
        </surface>
      </collision>
      <visual name='right_bogie_link_visual'>
        <pose>0 0 0 0 -0 0</pose>
        <geometry>
          <mesh>
            <scale>1 1 1</scale>
            <uri>model://sawppy/meshes/bases/right_bogie_asm.stl</uri>
          </mesh>
        </geometry>
        <material>
          <script>
            <name>Gazebo/DarkGray</name>
            <uri>file://media/materials/scripts/gazebo.material</uri>
          </script>
        </material>
      </visual>
      <gravity>1</gravity>
      <velocity_decay/>
    </link>
    <joint name='back_right_steer_joint' type='revolute'>
      <pose relative_to='right_bogie_link'>-0.149 -0.05 0.0338 0 -0 0</pose>
      <parent>right_bogie_link</parent>
      <child>back_right_steer_link</child>
      <axis>
        <initial_position>0</initial_position>
        <xyz>0 0 1</xyz>
        <limit>
          <lower>-1e+16</lower>
          <upper>1e+16</upper>
        </limit>
        <dynamics>
          <spring_reference>0</spring_reference>
          <spring_stiffness>0</spring_stiffness>
          <damping>0.1</damping>
          <friction>0.1</friction>
        </dynamics>
      </axis>
      <physics>
        <provide_feedback>1</provide_feedback>
        <ode>
          <limit>
            <cfm>0</cfm>
            <erp>0.2</erp>
          </limit>
          <provide_feedback>1</provide_feedback>
        </ode>
      </physics>
    </joint>
    <link name='back_right_steer_link'>
      <pose relative_to='back_right_steer_joint'>0 0 0 0 -0 0</pose>
      <inertial>
        <pose>0 0 0 0 -0 0</pose>
        <mass>0.25</mass>
        <inertia>
          <ixx>0.000416667</ixx>
          <ixy>0</ixy>
          <ixz>0</ixz>
          <iyy>0.000416667</iyy>
          <iyz>0</iyz>
          <izz>0.000416667</izz>
        </inertia>
      </inertial>
      <collision name='back_right_steer_link_collision'>
        <pose>0 0 0 0 -0 0</pose>
        <geometry>
          <box>
            <size>0.1 0.1 0.1</size>
          </box>
        </geometry>
        <surface>
          <contact>
            <ode/>
          </contact>
          <friction>
            <ode/>
          </friction>
        </surface>
      </collision>
      <visual name='back_right_steer_link_visual'>
        <pose>0 0 0 0 -0 0</pose>
        <geometry>
          <mesh>
            <scale>1 1 1</scale>
            <uri>model://sawppy/meshes/bases/back_right_steering_asm.stl</uri>
          </mesh>
        </geometry>
        <material>
          <script>
            <name>Gazebo/DarkGray</name>
            <uri>file://media/materials/scripts/gazebo.material</uri>
          </script>
        </material>
      </visual>
      <gravity>1</gravity>
      <velocity_decay/>
    </link>
    <joint name='back_right_wheel_joint' type='revolute'>
      <pose relative_to='back_right_steer_link'>0 0 -0.132 0 -0 0</pose>
      <parent>back_right_steer_link</parent>
      <child>back_right_wheel_link</child>
      <axis>
        <initial_position>0</initial_position>
        <xyz>0 1 0</xyz>
        <limit>
          <lower>-1e+16</lower>
          <upper>1e+16</upper>
        </limit>
        <dynamics>
          <spring_reference>0</spring_reference>
          <spring_stiffness>0</spring_stiffness>
          <damping>0.01</damping>
          <friction>0.01</friction>
        </dynamics>
      </axis>
      <physics>
        <provide_feedback>1</provide_feedback>
        <ode>
          <limit>
            <cfm>0</cfm>
            <erp>0.2</erp>
          </limit>
          <provide_feedback>1</provide_feedback>
        </ode>
      </physics>
    </joint>
    <link name='back_right_wheel_link'>
      <pose relative_to='back_right_wheel_joint'>0 0 0 0 -0 0</pose>
      <inertial>
        <pose>0 0 0 0 -0 0</pose>
        <mass>0.25</mass>
        <inertia>
          <ixx>0.000433333</ixx>
          <ixy>0</ixy>
          <ixz>0</ixz>
          <iyy>0.000433333</iyy>
          <iyz>0</iyz>
          <izz>0.00045</izz>
        </inertia>
      </inertial>
      <collision name='back_right_wheel_link_collision'>
        <pose>0 0 0 -1.5708 0 0</pose>
        <geometry>
          <cylinder>
            <length>0.1</length>
            <radius>0.06</radius>
          </cylinder>
        </geometry>
        <surface>
          <contact>
            <ode/>
          </contact>
          <friction>
            <ode/>
          </friction>
        </surface>
      </collision>
      <visual name='back_right_wheel_link_visual'>
        <pose>0 0 0 -1.5708 0 0</pose>
        <geometry>
          <mesh>
            <scale>1 1 1</scale>
            <uri>model://sawppy/meshes/wheels/wheel_asm.stl</uri>
          </mesh>
        </geometry>
        <material>
          <script>
            <name>Gazebo/DarkGray</name>
            <uri>file://media/materials/scripts/gazebo.material</uri>
          </script>
        </material>
      </visual>
      <gravity>1</gravity>
      <velocity_decay/>
    </link>
    <joint name='mid_right_wheel_joint' type='revolute'>
      <pose relative_to='right_bogie_link'>0.1063 -0.0929 -0.0959 0 -0 0</pose>
      <parent>right_bogie_link</parent>
      <child>mid_right_wheel_link</child>
      <axis>
        <initial_position>0</initial_position>
        <xyz>0 1 0</xyz>
        <limit>
          <lower>-1e+16</lower>
          <upper>1e+16</upper>
        </limit>
        <dynamics>
          <spring_reference>0</spring_reference>
          <spring_stiffness>0</spring_stiffness>
          <damping>0.01</damping>
          <friction>0.01</friction>
        </dynamics>
      </axis>
      <physics>
        <provide_feedback>1</provide_feedback>
        <ode>
          <limit>
            <cfm>0</cfm>
            <erp>0.2</erp>
          </limit>
          <provide_feedback>1</provide_feedback>
        </ode>
      </physics>
    </joint>
    <link name='mid_right_wheel_link'>
      <pose relative_to='mid_right_wheel_joint'>0 0 0 0 -0 0</pose>
      <inertial>
        <pose>0 0 0 0 -0 0</pose>
        <mass>0.25</mass>
        <inertia>
          <ixx>0.000433333</ixx>
          <ixy>0</ixy>
          <ixz>0</ixz>
          <iyy>0.000433333</iyy>
          <iyz>0</iyz>
          <izz>0.00045</izz>
        </inertia>
      </inertial>
      <collision name='mid_right_wheel_link_collision'>
        <pose>0 0 0 -1.5708 0 0</pose>
        <geometry>
          <cylinder>
            <length>0.1</length>
            <radius>0.06</radius>
          </cylinder>
        </geometry>
        <surface>
          <contact>
            <ode/>
          </contact>
          <friction>
            <ode/>
          </friction>
        </surface>
      </collision>
      <visual name='mid_right_wheel_link_visual'>
        <pose>0 0 0 -1.5708 0 0</pose>
        <geometry>
          <mesh>
            <scale>1 1 1</scale>
            <uri>model://sawppy/meshes/wheels/wheel_asm.stl</uri>
          </mesh>
        </geometry>
        <material>
          <script>
            <name>Gazebo/DarkGray</name>
            <uri>file://media/materials/scripts/gazebo.material</uri>
          </script>
        </material>
      </visual>
      <gravity>1</gravity>
      <velocity_decay/>
    </link>
    <!-- <plugin name='gazebo_ros_control' filename='libgazebo_ros_control.so'>
      <robotNamespace>/</robotNamespace>
      <robotSimType>gazebo_ros_control/DefaultRobotHWSim</robotSimType>
      <legacyModeNS>0</legacyModeNS>
    </plugin> -->
    <!-- <plugin name='gazebo_ros_joint_state_publisher' filename='libgazebo_ros_joint_state_publisher.so'>
      <robotNamespace>/</robotNamespace>
      <jointName>left_rocker_joint, right_rocker_joint, left_bogie_joint, right_bogie_joint, diff_brace_joint, back_left_turnbuckle_joint, back_right_turnbuckle_joint, front_left_turnbuckle_joint, front_right_turnbuckle_joint</jointName>
      <updateRate>50</updateRate>
      <alwaysOn>1</alwaysOn>
    </plugin> -->
    <link name='left_turnbuckle_link'>
      <pose>0.035 0.17 0.07 0 -0 0</pose>
      <visual name='left_turnbuckle_visual'>
        <pose>0 0 0 0 -0 0</pose>
        <geometry>
          <mesh>
            <uri>model://curio/meshes/bases/turnbuckle.stl</uri>
          </mesh>
        </geometry>
        <material>
          <script>
            <name>Gazebo/Blue</name>
            <uri>__default__</uri>
          </script>
        </material>
      </visual>
      <collision name='left_turnbuckle_collision'>
        <pose>0 0 0 0 1.5708 0</pose>
        <geometry>
          <cylinder>
            <length>0.07</length>
            <radius>0.0025</radius>
          </cylinder>
        </geometry>
      </collision>
      <inertial>
        <mass>0.01</mass>
        <inertia>
          <ixx>0.0001</ixx>
          <ixy>0</ixy>
          <ixz>0</ixz>
          <iyy>0.0001</iyy>
          <iyz>0</iyz>
          <izz>0.0001</izz>
        </inertia>
      </inertial>
    </link>
    <joint name='back_left_turnbuckle_joint' type='ball'>
      <pose>-0.035 0 0 0 -0 0</pose>
      <parent>diff_brace_link</parent>
      <child>left_turnbuckle_link</child>
    </joint>
    <joint name='front_left_turnbuckle_joint' type='ball'>
      <pose>0.035 0 0 0 -0 0</pose>
      <parent>left_rocker_link</parent>
      <child>left_turnbuckle_link</child>
    </joint>
    <static>0</static>
    <link name='right_turnbuckle_link'>
      <pose>0.035 -0.17 0.07 0 -0 0</pose>
      <visual name='right_turnbuckle_visual'>
        <pose>0 0 0 0 -0 0</pose>
        <geometry>
          <mesh>
            <uri>model://curio/meshes/bases/turnbuckle.stl</uri>
          </mesh>
        </geometry>
        <material>
          <script>
            <name>Gazebo/Blue</name>
            <uri>__default__</uri>
          </script>
        </material>
      </visual>
      <collision name='right_turnbuckle_collision'>
        <pose>0 0 0 0 1.5708 0</pose>
        <geometry>
          <cylinder>
            <length>0.07</length>
            <radius>0.0025</radius>
          </cylinder>
        </geometry>
      </collision>
      <inertial>
        <mass>0.01</mass>
        <inertia>
          <ixx>0.0001</ixx>
          <ixy>0</ixy>
          <ixz>0</ixz>
          <iyy>0.0001</iyy>
          <iyz>0</iyz>
          <izz>0.0001</izz>
        </inertia>
      </inertial>
    </link>
    <joint name='back_right_turnbuckle_joint' type='ball'>
      <pose>-0.035 0 0 0 -0 0</pose>
      <parent>diff_brace_link</parent>
      <child>right_turnbuckle_link</child>
    </joint>
    <joint name='front_right_turnbuckle_joint' type='ball'>
      <pose>0.035 0 0 0 -0 0</pose>
      <parent>right_rocker_link</parent>
      <child>right_turnbuckle_link</child>
    </joint>
  </model>
</sdf>
